# 45장 프로미스

비동기 처리를 위한 하나의 패턴으로 콜백 함수를 사용한다.  
하지만 콜백 함수에는 많은 단점들이 존재하고, 이를 해결하기 위해 ES6에서는 비동기 처리를 위해 프로미스를 도입했다. 
프로미스는 비동기 처리 상태와 처리 결과를 관리하는 객체이다.
## 45.1 비동기 처리를 위한 콜백 패턴의 단점
1. 콜백헬
  ```js
  const get = (url, callback) => {
    const xhr = new XMLHttpRequest() // xhr 객체 생성
    xhr.open("GET", url) // HTTP 초기화
    xhr.send() // HTTP 전송

    // onload 이벤트 핸들러는 응답이 온 경우에 실행
    xhr.onload = () => {
      if (xhr.status === 200) {
        callback(JSON.parse(xhr.response))
      } else {
        console.error(xhr.status)
      }
    }
  }

  get(`https://getmyinfo.com/posts/1`, (data) => {
    const userId = data.userId // 받은 data의 userId
    console.log(userId)
    // post에서 가져온 userId를 이용해서 user정보를 획득
    get(`https://getmyinfo.com/users/${userId}`,
        (userInfo) => {
      console.log(userInfo)
    })
  })
  ```
  
  - 처음 posts/1에서 Id를 이용해서 정보 가져오고, 그 가져온 정보 안에서 userId를 가지고 또 user의 정보를 가져오는 요청을 한 것이다.  
    실행되는 함수를 보면 get이라는 비동기 함수 안에 또 get이라는 비동기 함수가 있다.  
    여기서 안에 있는 get 함수는 첫번째 요청이 성공했을 경우에만 동작하는 콜백 함수인 것이다(인자로 전달).  
    벌써부터 **가독성이 좋지 않고, 실수를 유발하는 경우가 많아진다. 또한 디버깅이 쉽지 않다.**  

2. 에러 처리의 한계
  - `try-catch`문으로 애러를 알려주는 코드를 작성했다.
    ```js
    try{
      setTimeout(()=>{throw new Error('error')},100) // 비동기메서드
    }catch(e){
      console.error(e)
    }
    ```
    이를 실행시켜보면 애러가 캐치되지 않는다.
    `setTimeout`이 호출되면 실행 컨텍스트가 콜스택에 푸시되고 바로 실행되서 제거가 된다. 
    이는 setTimeout이 비동기함수이기 때문이다.  
    이후 타이머가 끝나면 setTimeout이 태스크퓨로 푸시되고 콜스택이 빈 후에 콜스택으로 푸시되어 실행된다.  
    따라서 콜백함수가 발생시킨 에러는 catch 블록에서 캐치되지 않는다.

## 45.2 프로미스 생성
:`promise` 생성자 함수는 new와 함께 호출되며 호출시 promise 객체를 생성한다.  
표준 빌트인 객체이다.  
성공시 `resolve`함수를 호출하고, 실패시 `reject`함수를 호출한다.
```js
const promise = new Promise((resolve, reject)=>{
  if(xhr.status === 200){
    resolve()
  }else{
    reject()
  }
})
```
|프로미스 상태|의미|상태 변경 조건|
|:----------:|----|----|
|pending|비동기 처리가 아직 수행되지 않은 상태|프로미스가 생성된 직후 기본 상태|
|fulfilled|비동기 처리 성공|resolve 함수 호출|
|rejected|비동기 처리 실패|reject 함수 호출|

## 45.3 프로미스의 후속 처리 메서드
비동기 함수가 실행되고 이에따라 성공, 실패에 대한 처리를 해주어야한다.  
### Promise.then
then은 두개의 메서드를 인수로 받아온다.  
- 첫번째 : 프로미스 상태가 fulfilled가 되면 호출 된다. 이때 콜백 함수는 프로미스의 비동기 처리 결과를 인수로 받는다.
- 두번째 : 프로미스 상태가 reject가 되면 호출 된다. 이때 콜백 함수는 프로미스의 에러를 인수로 받는다.

### Promise.catch
catch는 프로미스가 rejected상태인 경우에만 호출된다. then과 동일하게 동작하며 promise를 반환한다.
### Promise.finally
finally는 성공 실패 여부에 상관 없이 무조건 한 번 호출된다. 
이 역시 promise를 반환한다. 

## 45.4 프로미스의 에러 처리
- then 메서드의 두번째 콜백 함수로 처리
  ```js
  promiseGet(wrongUrl)
    .then(
      res => console.log(res),
      err => console.log(err)
    )
  ```
- catch를 사용해 처리
  ```js
  promiseGet(wrongUrl)
    .then(res => console.log(res))
    .catch(err => console.log(err))
  ```
then의 두번째 콜백함수로 처리하는 방법 보다 catch를 이용하는 방법이 가독성이 더 좋다.  
catch메서드를 사용하면 then 메서드를 호출하며 발생한 에러 뿐 아니라 then메서드 내부에서 발생한 에까지 모두 캐치할 수 있다.  
그러므로 then 보다 catch를 사용할 것을 권장한다. 

## 45.6 프로미스의 정적 메서드
### Promise.resolve/Promise.reject
Promise.resolve/Promise.reject는 이미 존재하는 값을 래핑하여 프로미스를 생성하기 위해 사용한다.  
```js
const resolvedPromise = new Promise(resolve => resolve([1,2,3]))
// 동일 =
const resolvedPromise = new Promise.resolve([1,2,3])
resolvedPromise.then(console.log) //[1,2,3]

const rejectedPromise = new Promise(_,reject)=> reject(new Error('Error')))
// 동일 =
const rejectedPromise = new Promise.reject(new Error('Error'))
rejectedPromise.then(console.log) //Error: Error
```

### Promise.all
여러개의 비동기 처리를 병렬처리할 때 사용한다.  
모든 요소가 정상적으로 처리되면 then으로 넘어간다.
중간에 하나라도 실패하면 바로 catch 메서드로 전달된다. 
```js
const requestData1 = () => 
    new Promise(resolve => setTimeout(()=>resolve(1),3000))
  const requestData2 = () => 
    new Promise(resolve => setTimeout(()=>resolve(2),2000))
  const requestData3 = () => 
    new Promise(resolve => setTimeout(()=>resolve(3),1000))

  Promise.all([requestData1(),requestData2(),requestData3()])
    .then(console.log) // [ 1, 2, 3 ] (3초후)
    .catch(console.error)
```

### Promise.race
Promise.all과 달리 먼저 fulfilled상태가 되는 메서드만 결과로 반환한다.

### Promise.allSettled
프로미스를 요소로 갖는 배열들의 이터러블을 인수로 받는다.  
결과는 프로미스가 fulfilled상태인 경우 비동기 처리 상태를 나타내는 status 프로퍼티와 value프로퍼티를 갖는다. 
프로미스가 rejected 상태인 경우 비동기 상태를 나타내는 status 프로퍼티와 에러를 나타내는 reason 프로퍼티를 갖는다.

## 45.7 마이크로태스크 큐
마이크로 테스크 큐는 테스크 큐와 별도의 큐이다.  
마이크로 테스크 큐는 테스크큐보다 우선순위가 높다.  
그래서 아래와 같은 결과가 나온다.
```js
setTimeout(()=>console.log(1),0)

Promise.resolve()
  .then(() => console.log(2))
  .then(() => console.log(3))

// 2 -> 3 -> 1
```
이벤트 루프는 콜 스택이 비면 마이크로태스크 큐의 함수를 먼저 가져와 실행 시킨다. 

## 45.8 fetch
fetch 함수는 HTTP 요청 전송 기능을 제공하는 클라이언트 사이드 WebAPI이다.  
```js
const promise = fetch(url[, options])
```

```js
//get
request.get('url')
  .then(response => response.json())
  .catch(err => console.error(err))

//post,patch,delete
request.post('url',{
  userID: 1,
  title: 'abc',
  completed: false
})
  .then(response => response.json())
  .catch(err => console.error(err))

```